Workbook

Sheet Dashboard
A1: Flour Frontier · All Cities Ranking Dashboard
A2: 50 Cities · 6 Weighted Lenses
A3: Sensitivity Lens | B3: Weight | C3: What it means
A4: Market Opportunity | B4: 30% | C4: Size of the prize: market size, gap to parity, underpenetration, accessible distributor/operator base.
A5: GMI Performance | B5: 20% | C5: Whether GMI is growing or losing ground; recent YoY performance and repeatability of wins/losses.
A6: Economic Stability | B6: 15% | C6: Consistency of local economy, industry diversity, and resilience of foodservice/bakery demand.
A7: Future Growth | B7: 15% | C7: Population growth and migration momentum only.
A8: HQ Inflow | B8: 10% | C8: Company movement, corporate anchors, industry mix, and how those affect foodservice density.
A9: Transport Quality | B9: 10% | C9: Cost-to-serve based on proximity to mills/warehouses and truck vs intermodal complexity.
A10: Top 5 Overall | D10: Bottom 5 Overall
A11: Rank | B11: City | C11: Weighted Score | D11: Rank | E11: City | F11: Weighted Score
A12: 1 | B12: =INDEX('All Cities Ranking'!$B$2:$B$51,MATCH(1,'All Cities Ranking'!$A$2:$A$51,0)) -> Houston | C12: =INDEX('All Cities Ranking'!$E$2:$E$51,MATCH(1,'All Cities Ranking'!$A$2:$A$51,0)) -> 4.35 | D12: 1 | E12: =INDEX('All Cities Ranking'!$B$2:$B$51,MATCH(LARGE('All Cities Ranking'!$A$2:$A$51,1),'All Cities Ranking'!$A$2:$A$51,0)) -> Cleveland | F12: =INDEX('All Cities Ranking'!$E$2:$E$51,MATCH(LARGE('All Cities Ranking'!$A$2:$A$51,1),'All Cities Ranking'!$A$2:$A$51,0)) -> 1.45
A13: 2 | B13: =INDEX('All Cities Ranking'!$B$2:$B$51,MATCH(2,'All Cities Ranking'!$A$2:$A$51,0)) -> Dallas-Fort Worth | C13: =INDEX('All Cities Ranking'!$E$2:$E$51,MATCH(2,'All Cities Ranking'!$A$2:$A$51,0)) -> 3.95 | D13: 2 | E13: =INDEX('All Cities Ranking'!$B$2:$B$51,MATCH(LARGE('All Cities Ranking'!$A$2:$A$51,2),'All Cities Ranking'!$A$2:$A$51,0)) -> Louisville | F13: =INDEX('All Cities Ranking'!$E$2:$E$51,MATCH(LARGE('All Cities Ranking'!$A$2:$A$51,2),'All Cities Ranking'!$A$2:$A$51,0)) -> 2.35
A14: 3 | B14: =INDEX('All Cities Ranking'!$B$2:$B$51,MATCH(3,'All Cities Ranking'!$A$2:$A$51,0)) -> Atlanta | C14: =INDEX('All Cities Ranking'!$E$2:$E$51,MATCH(3,'All Cities Ranking'!$A$2:$A$51,0)) -> 3.5 | D14: 3 | E14: =INDEX('All Cities Ranking'!$B$2:$B$51,MATCH(LARGE('All Cities Ranking'!$A$2:$A$51,3),'All Cities Ranking'!$A$2:$A$51,0)) -> Detroit | F14: =INDEX('All Cities Ranking'!$E$2:$E$51,MATCH(LARGE('All Cities Ranking'!$A$2:$A$51,3),'All Cities Ranking'!$A$2:$A$51,0)) -> 2.355
A15: 4 | B15: =INDEX('All Cities Ranking'!$B$2:$B$51,MATCH(4,'All Cities Ranking'!$A$2:$A$51,0)) -> Tampa | C15: =INDEX('All Cities Ranking'!$E$2:$E$51,MATCH(4,'All Cities Ranking'!$A$2:$A$51,0)) -> 3.3 | D15: 4 | E15: =INDEX('All Cities Ranking'!$B$2:$B$51,MATCH(LARGE('All Cities Ranking'!$A$2:$A$51,4),'All Cities Ranking'!$A$2:$A$51,0)) -> Providence | F15: =INDEX('All Cities Ranking'!$E$2:$E$51,MATCH(LARGE('All Cities Ranking'!$A$2:$A$51,4),'All Cities Ranking'!$A$2:$A$51,0)) -> 2.45
A16: 5 | B16: =INDEX('All Cities Ranking'!$B$2:$B$51,MATCH(5,'All Cities Ranking'!$A$2:$A$51,0)) -> Phoenix | C16: =INDEX('All Cities Ranking'!$E$2:$E$51,MATCH(5,'All Cities Ranking'!$A$2:$A$51,0)) -> 2.8 | D16: 5 | E16: =INDEX('All Cities Ranking'!$B$2:$B$51,MATCH(LARGE('All Cities Ranking'!$A$2:$A$51,5),'All Cities Ranking'!$A$2:$A$51,0)) -> Raleigh | F16: =INDEX('All Cities Ranking'!$E$2:$E$51,MATCH(LARGE('All Cities Ranking'!$A$2:$A$51,5),'All Cities Ranking'!$A$2:$A$51,0)) -> 2.53

Sheet Methodology
A1: Topic | B1: Explanation
A2: Why these lenses | B2: I chose these six lenses because the goal is not just to identify the biggest flour markets, but to rank which cities deserve the most strategic attention. Market Opportunity gets the highest weight because it captures the size of the prize and the gap to parity. GMI Performance shows whether we are already gaining or losing momentum. Economic Stability protects the ranking from overvaluing volatile markets. Future Growth keeps the model pointed toward where demand is moving. HQ Inflow captures business migration and industry mix, which influence foodservice density and flour demand. Transport Quality accounts for cost-to-serve and whether the market can be supported efficiently through the current GMI mill and warehouse network.
A3: Market Opportunity · 30% | B3: Includes total flour demand, current GMI share/index, gap to parity, underpenetration, distributor strength, foodservice/bakery density, and whether upside is realistically accessible.
A4: GMI Performance · 20% | B4: Measures whether GMI is growing or losing ground: YoY growth, volume trend, distributor performance, and whether losses are market-driven or execution-driven.
A5: Economic Stability · 15% | B5: Measures durability of the local economy: industry diversity, business climate, job consistency, exposure to cyclical sectors, and stability of foodservice demand.
A6: Population Growth · 15% | B6: Pure population growth lens: 10-year projection, recent CAGR, migration momentum, and whether the metro is gaining or losing residents.
A7: HQ Inflow · 10% | B7: Company movement and corporate/industry anchors: companies moving in/out, HQ expansions, industries such as tech, healthcare, logistics, hospitality, QSR, and manufacturing, and expected impact on flour demand.
A8: Transport Quality · 10% | B8: Cost-to-serve lens: proximity to GMI mills and warehouses, truck vs intermodal reliance, long-haul complexity, and whether a proposed warehouse/toll-mill would improve economics.
A9: Score scale | B9: Each lens is scored 1 to 5, where 5 is strongest. Weighted Score = Market Opportunity 30% + GMI Performance 20% + Economic Stability 15% + Future Growth 15% + HQ Inflow 10% + Transport Quality 10%.
A10: Ranking rule | B10: Overall Rank locks the final True 5 first — Houston, Dallas-Fort Worth, Atlanta, Tampa, Phoenix — because that is the final strategic recommendation. Cities 6+ are ranked by the same weighted model underneath the True 5.

Sheet Lens Scores
A1: Overall Rank | B1: City / Metro | C1: Region | D1: AE / Owner | E1: Weighted Score | F1: Market Opportunity Score | G1: GMI Performance Score | H1: Economic Stability Score | I1: Population Growth Score | J1: HQ Inflow Score | K1: Transport Quality Score
A2: 1 | B2: Houston | C2: South | D2: Gus Patrick | E2: 4.35 | F2: 5 | G2: 5 | H2: 4 | I2: 3 | J2: 4 | K2: 4
A3: 2 | B3: Dallas-Fort Worth | C3: South | D3: Open (Melissa Magsalin) | E3: 3.95 | F3: 4 | G3: 2 | H3: 5 | I3: 4 | J3: 5 | K3: 5
A4: 3 | B4: Atlanta | C4: South | D4: Josh Cohen | E4: 3.5 | F4: 3 | G4: 5 | H4: 4 | I4: 2 | J4: 5 | K4: 2
A5: 4 | B5: Tampa | C5: South | D5: Jeffrey Santiago | E5: 3.3 | F5: 3 | G5: 4 | H5: 5 | I5: 3 | J5: 3 | K5: 1
A6: 5 | B6: Phoenix | C6: West | D6: Shotsie Wilson | E6: 2.8 | F6: 1 | G6: 4 | H6: 1 | I6: 5 | J6: 3 | K6: 5
A7: 6 | B7: Austin | C7: South | D7: Gus Patrick | E7: 3.62 | F7: 3.5 | G7: 5 | H7: 4.5 | I7: 1 | J7: 3.5 | K7: 4
A8: 7 | B8: Richmond | C8: South | D8: Lynn Allen | E8: 3.27 | F8: 3.5 | G8: 4 | H8: 4.8 | I8: 1 | J8: 2.5 | K8: 3
A9: 8 | B9: Oklahoma City | C9: South | D9: Tim Ryan | E9: 3.25 | F9: 3.5 | G9: 4 | H9: 4 | I9: 1 | J9: 2.5 | K9: 4
A10: 9 | B10: San Jose | C10: West | D10: Yoel Sharabi | E10: 3.22 | F10: 3 | G10: 3 | H10: 3.8 | I10: 2 | J10: 3.5 | K10: 5
A11: 10 | B11: St. Louis | C11: Central | D11: Tim Ryan | E11: 3.15 | F11: 2.6 | G11: 5 | H11: 3.8 | I11: 1 | J11: 2.5 | K11: 4
A12: 11 | B12: Denver | C12: West | D12: Shotsie Wilson | E12: 3.13 | F12: 3.6 | G12: 3 | H12: 4 | I12: 1 | J12: 2.5 | K12: 4.5
A13: 12 | B13: Washington DC | C13: South | D13: Lynn Allen | E13: 3.13 | F13: 3 | G13: 4 | H13: 4.2 | I13: 1 | J13: 2.5 | K13: 4
... A51: 50 | B51: Cleveland | C51: Central | D51: Dean Psyhogios | E51: 2.35 | F51: 3 | G51: 1 | H51: 3 | I51: 1 | J51: 2.5 | K51: 4

Sheet Top & Bottom Views
A1: View | B1: Rank in View | C1: City / Metro | D1: Overall Rank | E1: Score Used | F1: Opportunity Tier | G1: Key Action | H1: Why It Ranks Here
A2: Top 5 Overall | B2: 1 | C2: Houston | D2: 1 | E2: 4.35 | F2: True 5 Priority | G2: Prioritize | H2: GMI Index 49, biggest market opportunity in the country. ~8.8M lb annual gap to parity.
A3: Top 5 Overall | B3: 2 | C3: Dallas-Fort Worth | D3: 2 | E3: 3.95 | F3: True 5 Priority | G3: Prioritize | H3: DFW market growing +5.3% YoY. Sysco-CTX -38%, Sysco-NTX -36% are execution issues, not market issues.
A4: Top 5 Overall | B4: 3 | C4: Austin | D4: 6 | E4: 3.62 | F4: Watch List | G4: Develop / Monitor | H4: Under-penetrated at Index 75 and growing +16.3% GMI, the fastest in the set. Highest growth exposure on the board. Develop aggressively off Arlington WH.
A5: Top 5 Overall | B5: 4 | C5: Atlanta | D5: 3 | E5: 3.5 | F5: True 5 Priority | G5: Prioritize | H5: GFS-Shepherdsville already +122.5% YoY. Biggest cold spot in the network — Atlanta WH (if approved) is single biggest cost-to-serve opportunity in the country.
A6: Top 5 Overall | B6: 5 | C6: Tampa | D6: 4 | E6: 3.3 | F6: True 5 Priority | G6: Prioritize | H6: +13.9% GMI YoY (fastest True 5). Most expensive metro to serve at 2.2x truck baseline. Toll-mill or Atlanta WH would compress cost-to-serve.
A7: Bottom 5 Overall | B7: 1 | C7: Louisville | D7: 49 | E7: 2.35 | F7: Cold / Low Priority | G7: Defend | H7: High 35.1% share but GMI down 5.9%. Defend the base. Dean owns KY.
A8: Bottom 5 Overall | B8: 2 | C8: Cleveland | D8: 50 | E8: 2.35 | F8: Cold / Low Priority | G8: Monitor | H8: Shrinking population. Cleveland Clinic is the only real anchor.
A9: Bottom 5 Overall | B9: 3 | C9: Detroit | D9: 48 | E9: 2.35 | F9: Cold / Low Priority | G9: Monitor | H9: Aging demographics, shrinking workforce. Dean owns KY-OH-IN-IL-MI under James.
A10: Bottom 5 Overall | B10: 4 | C10: Providence | D10: 47 | E10: 2.45 | F10: Cold / Low Priority | G10: Defend | H10: YoY number is misleading. Some 'losses' were due to the distributors being out of NY and sales getting placed onto other AE's/metros. Defend the base in a mature market. Tim Cipriano owns CT, RI, MA, VT, NH, ME.
A11: Bottom 5 Overall | B11: 5 | C11: Raleigh | D11: 46 | E11: 2.53 | F11: Cold / Low Priority | G11: Monitor | H11: Near parity but soft this year against strong long-run population growth. Growth exposure play; Atlanta WH (if approved) would shorten the haul. Lynn owns Eastern NC.
A12: Top 5 - Market Opportunity | B12: 1 | C12: Houston | D12: 1 | E12: 5 | F12: True 5 Priority | G12: Prioritize | H12: GMI Index 49, biggest market opportunity in the country. ~8.8M lb annual gap to parity.
A13: Top 5 - Market Opportunity | B13: 2 | C13: Dallas-Fort Worth | D13: 2 | E13: 4 | F13: True 5 Priority | G13: Prioritize | H13: DFW market growing +5.3% YoY. Sysco-CTX -38%, Sysco-NTX -36% are execution issues, not market issues.
... A71: Bottom 5 - Transport Quality | B71: 5 | C71: Norfolk | D71: 43 | E71: 2 | F71: Steady | G71: Defend / Maintain | H71: Slightly under parity and steady. Hold and develop. Lynn owns VA.

Sheet All Cities Ranking
A1: Overall Rank | B1: City / Metro | C1: Opportunity Tier | D1: Key Action | E1: Weighted Score | F1: Market Opportunity Score | G1: GMI Performance Score | H1: Economic Stability Score | I1: Population Growth Score | J1: HQ Inflow Score | K1: Transport Quality Score | L1: Map Score | M1: Locked True 5 Rank | N1: Region | O1: GMI Zone | P1: AE / Owner | Q1: Top Distributor | R1: HQ Inflow / Companies | S1: Industries | T1: Map Volume / Index Field | U1: Map YoY Field | V1: 10-Year Growth Field | W1: Mill / Warehouse / Transport | X1: DMA Match | Y1: Total Industry Lbs | Z1: GMI Lbs | AA1: GMI Share % | AB1: GMI Growth | AC1: GMI Index Calc | AD1: Why It Ranks Here
A2: 1 | B2: Houston | C2: True 5 Priority | D2: Prioritize | E2: =SUM(F2*0.3,G2*0.2,H2*0.15,I2*0.15,J2*0.1,K2*0.1) -> 4.35 | F2: 5 | G2: 5 | H2: 4 | I2: 3 | J2: 4 | K2: 4 | L2: 5 | M2: 1 | N2: South | O2: WEST (Mueting) | P2: Gus Patrick | Q2: Labatt-San Antonio, Sysco-Houston | R2: Sysco, Hewlett Packard Enterprise, Phillips 66 | S2: Energy, petrochem, healthcare, hospitality, education | T2: ~88K (8.8M lb · Index 49 vs 100 parity) | U2: -4% | V2: +15-19% | W2: Kansas City (462 mi to Arlington WH, +240 mi truck) | Arlington WH (240 mi) | Intermodal + truck | X2: Houston, TX | Y2: 60315422 | Z2: 8768572 | AA2: 0.145 | AB2: 0.015 | AC2: 48.7 | AD2: GMI Index 49, biggest market opportunity in the country. ~8.8M lb annual gap to parity.
A3: 2 | B3: Dallas-Fort Worth | C3: True 5 Priority | D3: Prioritize | E3: =SUM(F3*0.3,G3*0.2,H3*0.15,I3*0.15,J3*0.1,K3*0.1) -> 3.95 | F3: 4 | G3: 2 | H3: 5 | I3: 4 | J3: 5 | K3: 5 | L3: 5 | M3: 2 | N3: South | O3: WEST (Mueting) | P3: Open (Melissa Magsalin) | Q3: Sysco-Central TX, Sysco-North TX | R3: Toyota, AT&T, McKesson, Charles Schwab | S3: Tech, finance, logistics, hospitality, manufacturing | T3: ~145K | U3: -12% | V3: +18-22% | W3: Kansas City (462 mi) | Arlington WH (25 mi) | Truck → Arlington WH | X3: Dallas-Ft. Worth, TX | Y3: 49767388 | Z3: 10166816 | AA3: 0.204 | AB3: 0.053 | AC3: 65 | AD3: DFW market growing +5.3% YoY. Sysco-CTX -38%, Sysco-NTX -36% are execution issues, not market issues.
A4: 3 | B4: Atlanta | C4: True 5 Priority | D4: Prioritize | E4: =SUM(F4*0.3,G4*0.2,H4*0.15,I4*0.15,J4*0.1,K4*0.1) -> 3.5 | F4: 3 | G4: 5 | H4: 4 | I4: 2 | J4: 5 | K4: 2 | L4: 5 | M4: 3 | N4: South | O4: EAST (Tiemeyer) | P4: Josh Cohen | Q4: Sysco-Atlanta | R4: Coca-Cola, Delta, Home Depot, Chick-fil-A, Mercedes-Benz | S4: Logistics, beverage, QSR HQs, hospitality, film/TV | T4: ~102K | U4: -6% | V4: +14-18% | W4: Kansas City (798 mi) | Mechanicsburg WH (770 mi) — Atlanta WH proposed | Long-haul intermodal rail | X4: Atlanta, GA/ AL/NC | Y4: 36774911 | Z4: 8769191 | AA4: 0.238 | AB4: -0.015 | AC4: 79.9 | AD4: GFS-Shepherdsville already +122.5% YoY. Biggest cold spot in the network — Atlanta WH (if approved) is single biggest cost-to-serve opportunity in the country.
A5: 4 | B5: Tampa | C5: True 5 Priority | D5: Prioritize | E5: =SUM(F5*0.3,G5*0.2,H5*0.15,I5*0.15,J5*0.1,K5*0.1) -> 3.3 | F5: 3 | G5: 4 | H5: 5 | I5: 3 | J5: 3 | K5: 1 | L5: 5 | M5: 4 | N5: South | O5: EAST (Tiemeyer) | P5: Jeffrey Santiago | Q5: Cheney Brothers, Sysco-West Coast FL | R5: Bloomin' Brands, Kforce & ConnectWise, KnowBe4, Sykes Enterprises, Amscot Financial, Raymond James Financial, Refresco | S5: Tourism, hospitality, healthcare, financial services, retirement economy | T5: ~54K | U5: -8% | V5: +19-23% | W5: Buffalo (1,001 mi) | Orlando WH (84 mi) — Atlanta WH (if approved) cuts SE haul | Long-haul rail → Orlando WH | X5: Tampa-St. Petersburg-Sarasota, FL | Y5: 34502075 | Z5: 9975811 | AA5: 0.289 | AB5: 0.139 | AC5: 101.1 | AD5: +13.9% GMI YoY (fastest True 5). Most expensive metro to serve at 2.2x truck baseline. Toll-mill or Atlanta WH would compress cost-to-serve.
A6: 5 | B6: Phoenix | C6: True 5 Priority | D6: Prioritize | E6: =SUM(F6*0.3,G6*0.2,H6*0.15,I6*0.15,J6*0.1,K6*0.1) -> 2.8 | F6: 1 | G6: 4 | H6: 1 | I6: 5 | J6: 3 | K6: 5 | L6: 5 | M6: 5 | N6: West | O6: WEST (Mueting) | P6: Shotsie Wilson | Q6: Shamrock Foods, Sysco-Arizona | R6: PetSmart, Banner Health, GoDaddy, Avnet, Insight Enterprises, U-Haul | S6: Semiconductors, healthcare, hospitality, construction, retirement | T6: ~71K | U6: +3% | V6: +22-26% | W6: Vernon, CA (370 mi) | Stockton WH (708 mi) | Direct truck — best transport story in network | AD6: Best-served True 5. West region GMI losing 1.1pp share, so this is the defensive anchor. Shamrock + Wilson playbook is replicable.
A7: 6 | B7: Austin | C7: Watch List | D7: Develop / Monitor | E7: =SUM(F7*0.3,G7*0.2,H7*0.15,I7*0.15,J7*0.1,K7*0.1) -> 3.625 | F7: 3.5 | G7: 5 | H7: 4.5 | I7: 1 | J7: 3.5 | K7: 4 | L7: 4 | N7: South | O7: WEST (Mueting) | P7: Gus Patrick | Q7: Hardie's, Sysco-Austin | R7: Tesla, Oracle, Samsung, Apple | S7: Tech, semiconductors, government, education, hospitality | T7: 5.93M lb GMI Index 75, 23.5% share | U7: +16.3% GMI | V7: +22-27% | W7: Kansas City (795 mi) | Arlington WH (195 mi) | Truck from Arlington WH | X7: Austin, TX | Y7: 25188081 | Z7: 5929072 | AA7: 0.235 | AB7: 0.163 | AC7: 75 | AD7: Under-penetrated at Index 75 and growing +16.3% GMI, the fastest in the set. Highest growth exposure on the board. Develop aggressively off Arlington WH.
A8: 7 | B8: Richmond | C8: Steady | D8: Defend / Maintain | E8: =SUM(F8*0.3,G8*0.2,H8*0.15,I8*0.15,J8*0.1,K8*0.1) -> 3.27 | F8: 3.5 | G8: 4 | H8: 4.8 | I8: 1 | J8: 2.5 | K8: 3 | L8: 4 | N8: South | O8: EAST (Tiemeyer) | P8: Lynn Allen | Q8: US Foods-Richmond, Performance Foodservice | R8: Dominon Energy, CarMax, Altria Group, Markel Group | S8: Finance, government, logistics, healthcare, manufacturing | T8: 2.96M lb GMI Index 77, 24.3% share | U8: +5.5% GMI | V8: +6-8% | W8: Buffalo (far) | Mechanicsburg WH (250 mi) | Direct truck | X8: Richmond-Petersburg, VA | Y8: 12199521 | Z8: 2959394 | AA8: 0.243 | AB8: 0.055 | AC8: 76.6 | AD8: Index 77 with +5.5% growth makes this a develop market. Lynn owns VA, MD, DC, DE, Eastern NC.
A9: 8 | B9: Oklahoma City | C9: Steady | D9: Defend / Maintain | E9: =SUM(F9*0.3,G9*0.2,H9*0.15,I9*0.15,J9*0.1,K9*0.1) -> 3.25 | F9: 3.5 | G9: 4 | H9: 4 | I9: 1 | J9: 2.5 | K9: 4 | L9: 4 | N9: South | O9: WEST (Mueting) | P9: Tim Ryan | Q9: Sysco-Oklahoma, Ben E. Keith | R9: Hobby Lobby, Love's Travel Stops, Sonic | S9: Energy, aerospace, government, healthcare, agriculture | T9: 2.66M lb GMI, Index 65, 20.6% share | U9: +8.2% GMI | V9: +8-11% | W9: Kansas City (350 mi) | Arlington WH (200 mi) | Truck from Arlington WH | X9: Oklahoma City, OK | Y9: 12931762 | Z9: 2663849 | AA9: 0.206 | AB9: 0.082 | AC9: 64.5 | AD9: Index 65 with +8.2% growth makes this a develop market. Tim Ryan covers KS, MO, AR, LA, MS.
A10: 9 | B10: San Jose | C10: Steady | D10: Defend | E10: =SUM(F10*0.3,G10*0.2,H10*0.15,I10*0.15,J10*0.1,K10*0.1) -> 3.22 | F10: 3 | G10: 3 | H10: 3.8 | I10: 2 | J10: 3.5 | K10: 5 | L10: 3 | N10: West | O10: WEST (Mueting) | P10: Yoel Sharabi | Q10: US Foods-Bay Area, Sysco-San Jose | R10: Apple, Nvidia, Cisco | S10: Tech, semiconductors, healthcare, hospitality | T10: Territory data (West, not in Circana panel) | U10: See territory | V10: 0 to +2% | W10: Vernon, CA (350 mi) | Stockton WH (70 mi) | Direct truck from Stockton WH | AD10: Affluent Silicon Valley demand served off Stockton WH. Mature, defend share. Yoel owns Northern CA.
A11: 10 | B11: St. Louis | C11: Steady | D11: Defend | E11: =SUM(F11*0.3,G11*0.2,H11*0.15,I11*0.15,J11*0.1,K11*0.1) -> 3.15 | F11: 2.6 | G11: 5 | H11: 3.8 | I11: 1 | J11: 2.5 | K11: 4 | L11: 4 | N11: Central | O11: WEST (Mueting) | P11: Tim Ryan | Q11: US Foods-St. Louis, Sysco-St. Louis | R11: Enterprise, Edward Jones, Anheuser-Busch InBev | S11: Healthcare, finance, agribusiness, logistics, beverage | T11: 3.34M lb GMI, Index 122, 37.0% share | U11: +21.1% GMI | V11: +1-3% | W11: Kansas City (250 mi) | Independence WH (250 mi) | Truck from KC mill | X11: St. Louis, MO/IL | Y11: 9025740 | Z11: 3341881 | AA11: 0.37 | AB11: 0.211 | AC11: 121.6 | AD11: High 37% share with GMI up 21.1%, served cheaply off the KC mill. Defend and ride the momentum. Tim Ryan owns MO.
A12: 11 | B12: Denver | C12: Steady | D12: Defend / Maintain | E12: =SUM(F12*0.3,G12*0.2,H12*0.15,I12*0.15,J12*0.1,K12*0.1) -> 3.13 | F12: 3.6 | G12: 3 | H12: 4 | I12: 1 | J12: 2.5 | K12: 4.5 | L12: 3 | N12: West | O12: WEST (Mueting) | P12: Shotsie Wilson | Q12: Shamrock Foods, US Foods-Denver | R12: Frontier, RE/MAX, Western Union, DaVita | S12: Aerospace, energy (oil & gas), tech, outdoor recreation, hospitality | T12: ~32K | U12: -1% | V12: +10-13% | W12: Kansas City (605 mi) | Stockton WH (1,100 mi) | Intermodal rail | AD12: Mountain West gateway. Shotsie owns AE relationship across CO, MT, WY, ID.
A13: 12 | B13: Washington DC | C13: Steady | D13: Defend | E13: =SUM(F13*0.3,G13*0.2,H13*0.15,I13*0.15,J13*0.1,K13*0.1) -> 3.13 | F13: 3 | G13: 4 | H13: 4.2 | I13: 1 | J13: 2.5 | K13: 4 | L13: 3 | N13: South | O13: EAST (Tiemeyer) | P13: Lynn Allen | Q13: US Foods-Manassas, Sysco-Baltimore-Washington | R13: Danaher, Fannie Mae, Carlyle Group, Xylem, Amtrak | S13: Government, defense, consulting, healthcare, education | T13: 12.5M lb GMI, Index 102, 31.1% share | U13: +5.7% GMI | V13: +6-9% | W13: Buffalo (370 mi) | Mechanicsburg WH (120 mi) | Direct truck | X13: Washington, DC (Hagerstown) MD/PA/VA/WV | Y13: 40166336 | Z13: 12477651 | AA13: 0.311 | AB13: 0.057 | AC13: 101.9 | AD13: At parity with healthy +5.7% GMI growth. Defend share and develop. Lynn owns VA, MD, DC, DE, Eastern NC.
A14: 13 | B14: Memphis | C14: Steady | D14: Defend / Maintain | E14: =SUM(F14*0.3,G14*0.2,H14*0.15,I14*0.15,J14*0.1,K14*0.1) -> 3.13 | F14: 3.5 | G14: 4 | H14: 4.2 | I14: 1 | J14: 2.5 | K14: 2.5 | L14: 3 | N14: South | O14: WEST (Mueting) | P14: Tim Ryan | Q14: US Foods-Memphis, Sysco-Memphis | R14: FedEx, AutoZone, St. Jude Children's Research Hospital | S14: Logistics, agribusiness, healthcare, manufacturing | T14: 1.70M lb GMI, Index 76, 23.4% share | U14: +4.8% GMI | V14: +3-5% | W14: Kansas City (490 mi) | Arlington WH (470 mi) | Truck / intermodal | X14: Memphis, TN/MS/AR | Y14: 7278132 | Z14: 1701711 | AA14: 0.234 | AB14: 0.048 | AC14: 76 | AD14: Index 76 with +4.8% growth. Logistics hub with develop upside. Tim Ryan covers AR, MS, the Mid-South.
A15: 14 | B15: San Francisco-Oakland | C15: Steady | D15: Defend | E15: =SUM(F15*0.3,G15*0.2,H15*0.15,I15*0.15,J15*0.1,K15*0.1) -> 3.12 | F15: 3 | G15: 3 | H15: 3.8 | I15: 2 | J15: 2.5 | K15: 5 | L15: 3 | N15: West | O15: WEST (Mueting) | P15: Yoel Sharabi | Q15: US Foods-Bay Area, Sysco-SF, Chefs Warehouse-West | R15: Salesforce, Wells Fargo | S15: Tech, finance, tourism, hospitality, biotech | T15: Territory data (West, not in Circana panel) | U15: See territory | V15: 0 to +2% | W15: Vernon, CA (380 mi) | Stockton WH (75 mi) | Direct truck from Stockton WH | AD15: Premium artisan and restaurant demand served off Stockton WH. Mature and expensive, defend the base. Yoel owns Northern CA.
A16: 15 | B16: Jacksonville | C16: Steady | D16: Defend / Maintain | E16: =SUM(F16*0.3,G16*0.2,H16*0.15,I16*0.15,J16*0.1,K16*0.1) -> 3.11 | F16: 2.6 | G16: 5 | H16: 4.2 | I16: 1 | J16: 2.5 | K16: 3 | L16: 4 | N16: South | O16: EAST (Tiemeyer) | P16: Jeffrey Santiago | Q16: Cheney Brothers, Sysco-Jacksonville | R16: GuideWell Mutual Holding Corp, Fidelity, Southeastern Grocers | S16: Logistics, finance, military, healthcare, port | T16: 3.85M lb GMI, Index 131, 38.6% share | U16: +18.1% GMI | V16: +12-15% | W16: Buffalo (far) | Orlando WH (140 mi) | Truck from Orlando WH | X16: Jacksonville, FL/GA | Y16: 9970288 | Z16: 3849052 | AA16: 0.386 | AB16: 0.181 | AC16: 130.7 | AD16: High 38.6% share and GMI up 18.1%, the strongest growth-on-strength in the set. Orlando WH keeps it cheap. Jeffrey owns FL ex-Panhandle.
A17: 16 | B17: Columbus, OH | C17: Steady | D17: Defend | E17: =SUM(F17*0.3,G17*0.2,H17*0.15,I17*0.15,J17*0.1,K17*0.1) -> 3.105 | F17: 2.6 | G17: 5 | H17: 4.5 | I17: 1 | J17: 2.5 | K17: 2.5 | L17: 4 | N17: Central | O17: WEST (Mueting) | P17: Dean Psyhogios | Q17: Gordon Food Service, US Foods-Columbus | R17: Cardinal Health, Huntington Bancshares, Bath & Body works, Bread Financial, Vertiv, Abercrombie & Fitch | S17: Tech, insurance, logistics, education, healthcare | T17: 2.25M lb GMI, Index 144, 25.1% share | U17: +14.1% GMI | V17: +8-11% | W17: Buffalo (320 mi) | Mechanicsburg WH (400 mi) | Truck / intermodal | X17: Columbus, OH | Y17: 8968538 | Z17: 2250705 | AA17: 0.251 | AB17: 0.141 | AC17: 143.9 | AD17: Index 144 and GMI up 14.1% with strong tech-driven population inflow. Defend and develop. Dean owns OH.
A18: 17 | B18: New York | C18: Steady | D18: Defend | E18: =SUM(F18*0.3,G18*0.2,H18*0.15,I18*0.15,J18*0.1,K18*0.1) -> 3.08 | F18: 2.1 | G18: 4 | H18: 4 | I18: 2 | J18: 3.5 | K18: 4 | L18: 2 | N18: Northeast | O18: EAST (Tiemeyer) | P18: Conrad Chan & Chuck Bootier | Q18: Driscoll Foods, US Foods-Metro NY | R18: JPMorgan Chase & Co, Goldman Sachs Group, Morgan Stanley, AMEX, BlackRock, Pfizer, Verizon | S18: Finance, media, hospitality, healthcare, education | T18: 78.8M lb GMI, Index 183, 57.5% share | U18: +8.6% GMI | V18: 0 to +2% | W18: Buffalo (370 mi) | Mechanicsburg WH (180 mi) | Direct truck | X18: New York, NY/CT/PA | Y18: 137153480 | Z18: 78811979 | AA18: 0.575 | AB18: 0.086 | AC18: 183.3 | AD18: Highest GMI share in the country at 57.5%. Mature and saturated â defend the base, do not over-invest. Conrad & Chuck own NYC, Long Island, NJ.
A19: 18 | B19: Philadelphia | C19: Steady | D19: Defend / Maintain | E19: =SUM(F19*0.3,G19*0.2,H19*0.15,I19*0.15,J19*0.1,K19*0.1) -> 3.075 | F19: 3 | G19: 3 | H19: 4.5 | I19: 1 | J19: 2.5 | K19: 5 | L19: 3 | N19: Northeast | O19: EAST (Tiemeyer) | P19: Lynn Allen | Q19: US Foods-Philadelphia, Performance Foodservice | R19: Comcast, Cencora, Aramark, Toll Brothers | S19: Healthcare, pharma, education, finance, logistics | T19: 17.5M lb GMI, Index 104, 32.0% share | U19: +0.3% GMI | V19: +2-4% | W19: Buffalo (370 mi) | Mechanicsburg WH (95 mi) | Direct truck | X19: Philadelphia, PA/DE/NJ | Y19: 54576044 | Z19: 17491111 | AA19: 0.32 | AB19: 0.003 | AC19: 103.8 | AD19: At national parity and stable. Mechanicsburg WH at 95 mi gives strong cost-to-serve. Hold share. Chuck owns Eastern PA, NJ, Eastern NY.
A20: 19 | B20: Riverside | C20: Steady | D20: Defend / Maintain | E20: =SUM(F20*0.3,G20*0.2,H20*0.15,I20*0.15,J20*0.1,K20*0.1) -> 3.075 | F20: 3 | G20: 3 | H20: 4.5 | I20: 1 | J20: 2.5 | K20: 5 | L20: 4 | N20: West | O20: WEST (Mueting) | P20: Nancy Muller | Q20: Sysco-Riverside, US Foods-Corona, BakeMark | R20: Bourns, Inc, K&N Engineering, Best Best & Krieger | S20: Logistics, warehousing, manufacturing, healthcare, retail | T20: Territory data (West, not in Circana panel) | U20: See territory | V20: +8-11% | W20: Vernon, CA (60 mi) | Stockton WH (400 mi) | Direct truck from Vernon | AD20: One of the fastest-growing population centers in California and a national logistics hub, close to the Vernon mill. Strong develop play with Hispanic ISB upside. Nancy owns Southern CA.
A21: 20 | B21: Sacramento | C21: Steady | D21: Defend / Maintain | E21: =SUM(F21*0.3,G21*0.2,H21*0.15,I21*0.15,J21*0.1,K21*0.1) -> 3.075 | F21: 3 | G21: 3 | H21: 4.5 | I21: 1 | J21: 2.5 | K21: 5 | L21: 3 | N21: West | O21: WEST (Mueting) | P21: Yoel Sharabi | Q21: US Foods-Sacramento, Sysco-Sacramento | R21: Sutter Health, UC Davis Health, VSP Vision | S21: Government, healthcare, education, agriculture, tech | T21: Territory data (West, not in Circana panel) | U21: See territory | V21: +6-8% | W21: Vernon, CA (385 mi) | Stockton WH (50 mi) | Direct truck from Stockton WH | X21: San Antonio, TX | Y21: 25999310 | Z21: 4612764 | AA21: 0.177 | AB21: 0.031 | AC21: 56.1 | AD21: Growing capital market near the Stockton WH, so cost-to-serve is strong. Hold and develop. Yoel owns Northern CA.
A22: 21 | B22: San Antonio | C22: Steady | D22: Defend / Maintain | E22: =SUM(F22*0.3,G22*0.2,H22*0.15,I22*0.15,J22*0.1,K22*0.1) -> 3.07 | F22: 3.9 | G22: 3 | H22: 4 | I22: 1 | J22: 2.5 | K22: 3 | L22: 4 | N22: South | O22: WEST (Mueting) | P22: Gus Patrick | Q22: Labatt-San Antonio, Sysco-San Antonio | R22: H-E-B, USAA, Valero | S22: Military, healthcare, tourism, energy, manufacturing | T22: 4.61M lb GMI, Index 56, 17.7% share | U22: +3.1% GMI | V22: +15-19% | W22: Kansas City (795 mi) | Arlington WH (270 mi) | Truck from Arlington WH | X22: Indianapolis, IN | Y22: 6360244 | Z22: 1759953 | AA22: 0.277 | AB22: 0.139 | AC22: 119.5 | AD22: Index 56 is the deepest under-penetration of the Texas metros, with +3.1% growth and a heavy Hispanic base. Prime independent Hispanic ISB target. Gus owns South Texas.
A23: 22 | B23: Indianapolis | C23: Steady | D23: Defend | E23: =SUM(F23*0.3,G23*0.2,H23*0.15,I23*0.15,J23*0.1,K23*0.1) -> 3.06 | F23: 2.6 | G23: 5 | H23: 4.2 | I23: 1 | J23: 2.5 | K23: 2.5 | L23: 3 | N23: Central | O23: WEST (Mueting) | P23: Dean Psyhogios | Q23: Gordon Food Service, US Foods-Indianapolis | R23: Eli Lilly and Company, Corteva, Elevance Health | S23: Logistics, manufacturing, life sciences, healthcare | T23: 1.76M lb GMI, Index 120, 27.7% share | U23: +13.9% GMI | V23: +5-7% | W23: Avon, IA (470 mi) | Mechanicsburg WH (560 mi) | Truck / intermodal | X23: Pittsburgh, PA/MD/WV | Y23: 7718796 | Z23: 3186892 | AA23: 0.413 | AB23: 0.147 | AC23: 154.7 | AD23: Above parity at Index 120 with +13.9% growth. Defend and develop. Dean owns IN.
A24: 23 | B24: Pittsburgh | C24: Steady | D24: Defend | E24: =SUM(F24*0.3,G24*0.2,H24*0.15,I24*0.15,J24*0.1,K24*0.1) -> 3.06 | F24: 2.1 | G24: 5 | H24: 4.2 | I24: 1 | J24: 2.5 | K24: 4 | L24: 4 | N24: Northeast | O24: EAST (Tiemeyer) | P24: Kevin Karbo | Q24: US Foods-Pittsburgh, Sysco-Pittsburgh | R24: PNC, Kraft-Heinz, PPG | S24: Healthcare, tech, education, finance, manufacturing | T24: 3.19M lb GMI, Index 155, 41.3% share | U24: +14.7% GMI | V24: +2-4% | W24: Buffalo (220 mi) | Mechanicsburg WH (200 mi) | Direct truck | X24: Cincinnati, OH/KY/IN | Y24: 7007976 | Z24: 1384666 | AA24: 0.198 | AB24: 0.079 | AC24: 86.1 | AD24: High 41.3% share and GMI up 14.7% in a flat-population market, so the gains are share-driven. Defend aggressively. Kevin owns WV, Western PA, Western NY.
A25: 24 | B25: Cincinnati | C25: Steady | D25: Defend / Maintain | E25: =SUM(F25*0.3,G25*0.2,H25*0.15,I25*0.15,J25*0.1,K25*0.1) -> 3.025 | F25: 3 | G25: 4 | H25: 4.5 | I25: 1 | J25: 2.5 | K25: 2.5 | L25: 3 | N25: Central | O25: WEST (Mueting) | P25: Dean Psyhogios | Q25: Gordon Food Service, US Foods-Cincinnati | R25: P&G, Kroger, Fifth Third | S25: Consumer goods, healthcare, finance, logistics, manufacturing | T25: 1.38M lb GMI, Index 86, 19.8% share | U25: +7.9% GMI | V25: +3-5% | W25: Avon, IA (590 mi) | Mechanicsburg WH (470 mi) | Truck / intermodal | AD25: Slightly under parity at Index 86 with +7.9% growth. Hold and develop. Dean owns OH-KY-IN.
A26: 25 | B26: Los Angeles | C26: Steady | D26: Defend / Maintain | E26: =SUM(F26*0.3,G26*0.2,H26*0.15,I26*0.15,J26*0.1,K26*0.1) -> 3.02 | F26: 3 | G26: 3 | H26: 3.8 | I26: 1 | J26: 3 | K26: 5 | L26: 3 | N26: West | O26: WEST (Mueting) | P26: Nancy Muller | Q26: BakeMark-LA, Greco SoCal, PFS-SoCal | R26: The Walt Disney Co, SpaceX, Warner Bros Entertainment | S26: Entertainment, aerospace, logistics, hospitality, manufacturing | T26: Territory data (West, not in Circana panel) | U26: See territory | V26: -1 to +1% | W26: Vernon, CA (in-market, ~5 mi) | Stockton WH (350 mi) | Direct truck â best cost-to-serve in network | X26: Baltimore, MD | Y26: 17554624 | Z26: 4844770 | AA26: 0.276 | AB26: -0.005 | AC26: 90.1 | AD26: Vernon mill sits inside the market, so cost-to-serve is the best anywhere. Mature dense market, but independent Hispanic bakeries are real whitespace. Replicate the El Super and Northgate model at the street level. Nancy owns Southern CA and HI.
A27: 26 | B27: Baltimore | C27: Steady | D27: Defend / Maintain | E27: =SUM(F27*0.3,G27*0.2,H27*0.15,I27*0.15,J27*0.1,K27*0.1) -> 3 | F27: 3 | G27: 3 | H27: 4 | I27: 1 | J27: 2.5 | K27: 5 | L27: 3 | N27: South | O27: EAST (Tiemeyer) | P27: Lynn Allen | Q27: US Foods-Baltimore, Sysco-Baltimore | R27: Under Armour, Johns Hopkins, T. Rowe Price Group | S27: Healthcare, biotech, defense, logistics, education | T27: 4.84M lb GMI, Index 90, 27.6% share | U27: -0.5% GMI | V27: +3-5% | W27: Buffalo (380 mi) | Mechanicsburg WH (95 mi) | Direct truck | X27: Orlando-Daytona Beach-Melbourne, FL | Y27: 30730205 | Z27: 10344879 | AA27: 0.337 | AB27: 0.063 | AC27: 120.3 | AD27: Slightly below parity and flat, but Mechanicsburg WH at 95 mi makes it cheap to serve. Steady-hold. Lynn owns MD, VA, DC, DE.
A28: 27 | B28: Orlando | C28: Steady | D28: Defend / Maintain | E28: =SUM(F28*0.3,G28*0.2,H28*0.15,I28*0.15,J28*0.1,K28*0.1) -> 2.95 | F28: 2.6 | G28: 4 | H28: 3.8 | I28: 1 | J28: 2.5 | K28: 4 | L28: 4 | N28: South | O28: EAST (Tiemeyer) | P28: Jeffrey Santiago | Q28: Cheney Brothers, Sysco-Central Florida | R28: Darden Restaurants, Travel + Leisure Co, AAA, Marriot | S28: Tourism, hospitality, healthcare, tech, defense sim | T28: 10.3M lb GMI, Index 120, 33.7% share | U28: +6.3% GMI | V28: +18-22% | W28: Buffalo (far) | Orlando WH (~12 mi, beside facility) | Direct truck â best SE cost-to-serve | AD28: Index 120, +6.3% GMI, and Orlando WH essentially co-located gives the best cost-to-serve in the Southeast. Pin nudged off the warehouse marker. Jeffrey owns FL ex-Panhandle.
A29: 28 | B29: San Diego | C29: Steady | D29: Defend / Maintain | E29: =SUM(F29*0.3,G29*0.2,H29*0.15,I29*0.15,J29*0.1,K29*0.1) -> 2.925 | F29: 3 | G29: 3 | H29: 3.5 | I29: 1 | J29: 3.5 | K29: 4 | L29: 3 | N29: West | O29: WEST (Mueting) | P29: Nancy Muller | Q29: BakeMark-San Diego, US Foods-San Diego, Sysco | R29: Qualcomm, LPL Financial, Qualcomm | S29: Defense, biotech, tourism, hospitality, cross-border trade | T29: Territory data (West, not in Circana panel) | U29: See territory | V29: +3-5% | W29: Vernon, CA (130 mi) | Stockton WH (480 mi) | Direct truck from Vernon | X29: Chicago, IL /IN | Y29: 29436777 | Z29: 5067421 | AA29: 0.172 | AB29: -0.02 | AC29: 62.2 | AD29: Second-largest SoCal market with a heavy Hispanic base, served off the Vernon mill. Independent Hispanic bakery whitespace mirrors the LA model. Nancy owns Southern CA.
A30: 29 | B30: Chicago | C30: Steady | D30: Defend / Maintain | E30: =SUM(F30*0.3,G30*0.2,H30*0.15,I30*0.15,J30*0.1,K30*0.1) -> 2.92 | F30: 3.5 | G30: 3 | H30: 3.8 | I30: 1 | J30: 3 | K30: 2.5 | L30: 2 | N30: Central | O30: WEST (Mueting) | P30: Dean Psyhogios | Q30: Gordon Food Service, US Foods-Chicago | R30: United Airlines, ADM, Conagra, MondelÄz | S30: Finance, manufacturing, logistics, food, healthcare | T30: 5.07M lb GMI, Index 62, 17.2% share | U30: -2.0% GMI | V30: -1 to +1% | W30: Avon, IA (330 mi) | Independence WH (510 mi) | Truck / intermodal | X30: Minneapolis-St. Paul, MN/WI | Y30: 18296698 | Z30: 4219575 | AA30: 0.231 | AB30: 0.038 | AC30: 72.2 | AD30: Index 62 means real under-penetration, but the market is declining and mature. Acknowledge our strong rep while focusing investment on growth-exposure metros. Dean owns IL-IN-OH-KY-MI.
A31: 30 | B31: Minneapolis | C31: Steady | D31: Defend / Maintain | E31: =SUM(F31*0.3,G31*0.2,H31*0.15,I31*0.15,J31*0.1,K31*0.1) -> 2.91 | F31: 3.6 | G31: 2 | H31: 4.2 | I31: 1 | J31: 2.5 | K31: 4 | L31: 2 | N31: Central | O31: WEST (Mueting) | P31: Open (Not Covered) | Q31: Sysco-Minnesota, Reinhart | R31: Target, Best Buy, US Bancorp, 3M, UnitedHealth, General Mills | S31: Retail HQs, healthcare, food (us!), agriculture, financial services | T31: ~28K | U31: -5% | V31: +4-7% | W31: Avon, IA (231 mi) | Independence WH (440 mi) | Direct truck | X31: Nashville, TN/KY | Y31: 19541363 | Z31: 8169717 | AA31: 0.418 | AB31: 0.035 | AC31: 152.4 | AD31: WHQ home market. Central region growing fastest +5.5% but ND-SD-NE-MN-IA-WI territory is uncovered.
A32: 31 | B32: Nashville | C32: Steady | D32: Defend / Maintain | E32: =SUM(F32*0.3,G32*0.2,H32*0.15,I32*0.15,J32*0.1,K32*0.1) -> 2.9 | F32: 3 | G32: 4 | H32: 4 | I32: 1 | J32: 2.5 | K32: 2 | L32: 4 | N32: South | O32: EAST (Tiemeyer) | P32: Josh Cohen | Q32: GFS, Sysco-Nashville | R32: HCA Healthcare, Nissan, Dollar General, Bridgestone | S32: Healthcare, music/entertainment, automotive, logistics | T32: ~31K | U32: +4% | V32: +17-21% | W32: Kansas City (533 mi) | Mechanicsburg WH (730 mi) | Intermodal — fringe truck range | AD32: GMI Index 152 — well above national parity. Strong territory with growth momentum from prior coverage; Josh Cohen now owns the relationship.
A33: 32 | B33: Salt Lake City | C33: Steady | D33: Defend / Maintain | E33: =SUM(F33*0.3,G33*0.2,H33*0.15,I33*0.15,J33*0.1,K33*0.1) -> 2.875 | F33: 3 | G33: 3 | H33: 4.5 | I33: 1 | J33: 3.5 | K33: 2 | L33: 4 | N33: West | O33: WEST (Mueting) | P33: Shotsie Wilson | Q33: Sysco-Intermountain, US Foods-Salt Lake | R33: Goldman Sachs, Adobe, Qualtrics | S33: Tech, finance, outdoor recreation, logistics, healthcare | T33: Territory data (West, not in Circana panel) | U33: See territory | V33: +12-15% | W33: Kansas City (920 mi) | Stockton WH (600 mi) | Truck / intermodal | X33: Milwaukee, WI | Y33: 8262973 | Z33: 647539 | AA33: 0.078 | AB33: -0.042 | AC33: 26.3 | AD33: One of the fastest-growing economies in the country with strong tech-driven inflow. Develop aggressively despite the longer haul. Shotsie owns UT.
A34: 33 | B34: Milwaukee | C34: Steady | D34: Defend / Maintain | E34: =SUM(F34*0.3,G34*0.2,H34*0.15,I34*0.15,J34*0.1,K34*0.1) -> 2.82 | F34: 3.9 | G34: 2 | H34: 4 | I34: 1 | J34: 2.5 | K34: 2.5 | L34: 2 | N34: Central | O34: WEST (Mueting) | P34: Open (Not Covered) | Q34: Sysco-Wisconsin, Gordon Food Service | R34: Northwestern Mutual, Johnson Controls, Rockwell Automation, Harley-Davidson, Milwaukee Tool | S34: Manufacturing, finance, healthcare, food and beverage | T34: 0.65M lb GMI, Index 26, 7.8% share | U34: -4.2% GMI | V34: +1-3% | W34: Avon, IA (370 mi) | Independence WH (470 mi) | Truck / intermodal | AD34: Index 26 and 7.8% share is deep under-penetration, but the market is soft and the ND-SD-NE-MN-IA-WI territory is uncovered. Whitespace if covered.
A35: 34 | B35: Seattle | C35: Steady | D35: Defend / Maintain | E35: =SUM(F35*0.3,G35*0.2,H35*0.15,I35*0.15,J35*0.1,K35*0.1) -> 2.81 | F35: 3.6 | G35: 3 | H35: 4.2 | I35: 1 | J35: 2.5 | K35: 1 | L35: 3 | N35: West | O35: WEST (Mueting) | P35: Yoel Sharabi | Q35: US Foods-Seattle, Sysco-Seattle | R35: Amazon, Starbucks, Zillow, Expedia | S35: Tech, aerospace, coffee/retail HQs, healthcare, maritime | T35: ~42K | U35: -2% | V35: +8-11% | W35: Great Falls, MT (~520 mi) | Stockton WH (810 mi) | Long-haul rail | X35: Boston, MA/ NH/VT | Y35: 39117557 | Z35: 13988483 | AA35: 0.358 | AB35: -0.041 | AC35: 132.6 | AD35: Mature market, regulatory headwinds. Great Falls is the natural mill anchor.
A36: 35 | B36: Boston | C36: Steady | D36: Defend / Maintain | E36: =SUM(F36*0.3,G36*0.2,H36*0.15,I36*0.15,J36*0.1,K36*0.1) -> 2.81 | F36: 3.6 | G36: 2 | H36: 4.2 | I36: 1 | J36: 2.5 | K36: 3 | L36: 2 | N36: Northeast | O36: EAST (Tiemeyer) | P36: Tim Cipriano | Q36: PFG-Springfield, Sysco-Boston | R36: GE, Gillette, Liberty Mutual, Vertex | S36: Healthcare, education (Harvard/MIT ecosystem), biotech, financial services | T36: ~48K | U36: -3% | V36: +3-6% | W36: Buffalo (455 mi) | Mechanicsburg WH (340 mi) | Truck | AD36: Mature, slow-growth, expensive. NE region has 56% GMI share already (saturated).
A37: 36 | B37: Las Vegas | C37: Steady | D37: Defend / Maintain | E37: =SUM(F37*0.3,G37*0.2,H37*0.15,I37*0.15,J37*0.1,K37*0.1) -> 2.8 | F37: 3 | G37: 3 | H37: 4 | I37: 1 | J37: 2.5 | K37: 3 | L37: 4 | N37: West | O37: WEST (Mueting) | P37: Shotsie Wilson | Q37: Westco-Las Vegas, US Foods-Las Vegas, Sysco | R37: Caesars, MGM, Las Vegas Sands | S37: Tourism, hospitality, gaming, logistics, construction | T37: Territory data (West, not in Circana panel) | U37: See territory | V37: +10-13% | W37: Vernon, CA (270 mi) | Stockton WH (560 mi) | Truck from Vernon | X37: Miami-Ft. Lauderdale, FL | Y37: 42944984 | Z37: 9888300 | AA37: 0.23 | AB37: -0.011 | AC37: 102 | AD37: High-volume tourism and hospitality demand with strong population growth, served off the Vernon mill. Develop play. Shotsie owns NV, UT, AZ, CO, NM.
A38: 37 | B38: Portland | C38: Steady | D38: Defend / Maintain | E38: =SUM(F38*0.3,G38*0.2,H38*0.15,I38*0.15,J38*0.1,K38*0.1) -> 2.775 | F38: 3 | G38: 3 | H38: 4.5 | I38: 1 | J38: 3.5 | K38: 1 | L38: 3 | N38: West | O38: WEST (Mueting) | P38: Yoel Sharabi | Q38: US Foods-Portland, Sysco-Portland, PFS | R38: Nike, Intel, Columbia Sportswear | S38: Tech, manufacturing, food and beverage, logistics | T38: Territory data (West, not in Circana panel) | U38: See territory | V38: +3-5% | W38: Great Falls, MT (far) | Stockton WH (640 mi) | Truck / intermodal | X38: Charlotte, NC/SC | Y38: 20523312 | Z38: 5748239 | AA38: 0.28 | AB38: 0.08 | AC38: 93 | AD38: Strong artisan and craft bakery demand. Watch enzyme and specialty milling in the PacNW (Cairnspring, Cascade) on freight and protein. Yoel owns OR.
A39: 38 | B39: Miami | C39: Steady | D39: Defend / Maintain | E39: =SUM(F39*0.3,G39*0.2,H39*0.15,I39*0.15,J39*0.1,K39*0.1) -> 2.77 | F39: 3 | G39: 3 | H39: 3.8 | I39: 1 | J39: 2.5 | K39: 3 | L39: 3 | N39: South | O39: EAST (Tiemeyer) | P39: Jeffrey Santiago | Q39: Cheney Brothers, Sysco-South Florida | R39: Palantir, World Kinect Corp, Lennar Corp, Ryder System, Royal Caribbean Group | S39: Tourism, trade, finance, healthcare, hospitality | T39: 9.89M lb GMI, Index 102, 23.0% share | U39: -1.1% GMI | V39: +5-8% | W39: Buffalo (far) | Orlando WH (205 mi) | Truck from Orlando WH | X39: New Orleans, LA/MS | Y39: 12874504 | Z39: 2727112 | AA39: 0.212 | AB39: -0.069 | AC39: 66.3 | AD39: At parity but flat. Dense Hispanic population makes independent Hispanic bakeries a real whitespace lane. Jeffrey owns all FL except the Panhandle.
A40: 39 | B40: Charlotte | C40: Steady | D40: Defend / Maintain | E40: =SUM(F40*0.3,G40*0.2,H40*0.15,I40*0.15,J40*0.1,K40*0.1) -> 2.75 | F40: 3 | G40: 3 | H40: 4 | I40: 1 | J40: 1.5 | K40: 3.5 | L40: 4 | N40: South | O40: EAST (Tiemeyer) | P40: Josh Cohen | Q40: US Foods-Charlotte, Sysco-Charlotte | R40: Truist, LendingTree, Honeywell, Lowe's, Bank of America, Duke Energy | S40: Banking, energy, tech, motorsports, healthcare | T40: ~38K | U40: +1% | V40: +16-20% | W40: Kansas City (897 mi) | Mechanicsburg WH (490 mi) — Atlanta WH (if approved) drops to ~250 mi | Intermodal rail | X40: Birmingham, AL (Ann & Tusc) | Y40: 6280324 | Z40: 1731421 | AA40: 0.276 | AB40: -0.009 | AC40: 92.9 | AD40: Strong HQ inflow story. Atlanta WH (if approved) shifts Charlotte from intermodal to direct truck.
...

Sheet Raw National Map
A1: name | B1: lat | C1: lng | D1: score | E1: rank | F1: tagline | G1: pop | H1: cagr | I1: censusRegion | J1: zone | K1: ae | L1: distributor | M1: hqInflow | N1: industries | O1: fy26eqc | P1: plYoY | Q1: growth10yr | R1: mill | S1: warehouse | T1: transport | U1: insight
A2: Houston | B2: 29.76 | C2: -95.37 | D2: 5 | E2: 1 | F2: Biggest accessible flour opportunity in the country | G2: 7.51M | H2: +1.42% | I2: South | J2: WEST (Mueting) | K2: Gus Patrick | L2: Labatt-San Antonio, Sysco-Houston | M2: Sysco, Hewlett Packard Enterprise, Phillips 66 | N2: Energy, petrochem, healthcare, hospitality, education | O2: ~88K (8.8M lb · Index 49 vs 100 parity) | P2: -4% | Q2: +15-19% | R2: Kansas City (462 mi to Arlington WH, +240 mi truck) | S2: Arlington WH (240 mi) | T2: Intermodal + truck | U2: GMI Index 49, biggest market opportunity in the country. ~8.8M lb annual gap to parity.
A3: Dallas-Fort Worth | B3: 32.78 | C3: -96.8 | D3: 5 | E3: 2 | F3: Largest market with biggest current bleed | G3: 8.10M | H3: +1.74% | I3: South | J3: WEST (Mueting) | K3: Open (Melissa Magsalin) | L3: Sysco-Central TX, Sysco-North TX | M3: Toyota, AT&T, McKesson, Charles Schwab | N3: Tech, finance, logistics, hospitality, manufacturing | O3: ~145K | P3: -12% | Q3: +18-22% | R3: Kansas City (462 mi) | S3: Arlington WH (25 mi) | T3: Truck → Arlington WH | U3: DFW market growing +5.3% YoY. Sysco-CTX -38%, Sysco-NTX -36% are execution issues, not market issues.
A4: Atlanta | B4: 33.75 | C4: -84.39 | D4: 5 | E4: 3 | F4: GFS partnership already validating Southeast play | G4: 6.30M | H4: +1.28% | I4: South | J4: EAST (Tiemeyer) | K4: Josh Cohen | L4: Sysco-Atlanta | M4: Coca-Cola, Delta, Home Depot, Chick-fil-A, Mercedes-Benz | N4: Logistics, beverage, QSR HQs, hospitality, film/TV | O4: ~102K | P4: -6% | Q4: +14-18% | R4: Kansas City (798 mi) | S4: Mechanicsburg WH (770 mi) — Atlanta WH proposed | T4: Long-haul intermodal rail | U4: GFS-Shepherdsville already +122.5% YoY. Biggest cold spot in the network — Atlanta WH (if approved) is single biggest cost-to-serve opportunity in the country.
A5: Tampa | B5: 27.95 | C5: -82.46 | D5: 5 | E5: 4 | F5: Fastest GMI growth among True 5 | G5: 3.34M | H5: +1.51% | I5: South | J5: EAST (Tiemeyer) | K5: Jeffrey Santiago | L5: Cheney Brothers, Sysco-West Coast FL | M5: Bloomin' Brands, Kforce & ConnectWise, KnowBe4, Sykes Enterprises, Amscot Financial, Raymond James Financial, Refresco | N5: Tourism, hospitality, healthcare, financial services, retirement economy | O5: ~54K | P5: -8% | Q5: +19-23% | R5: Buffalo (1,001 mi) | S5: Orlando WH (84 mi) — Atlanta WH (if approved) cuts SE haul | T5: Long-haul rail → Orlando WH | U5: +13.9% GMI YoY (fastest True 5). Most expensive metro to serve at 2.2x truck baseline. Toll-mill or Atlanta WH would compress cost-to-serve.
A6: Phoenix | B6: 33.45 | C6: -112.07 | D6: 5 | E6: 5 | F6: Only True 5 with positive YoY in losing region | G6: 5.10M | H6: +1.82% | I6: West | J6: WEST (Mueting) | K6: Shotsie Wilson | L6: Shamrock Foods, Sysco-Arizona | M6: PetSmart, Banner Health, GoDaddy, Avnet, Insight Enterprises, U-Haul | N6: Semiconductors, healthcare, hospitality, construction, retirement | O6: ~71K | P6: +3% | Q6: +22-26% | R6: Vernon, CA (370 mi) | S6: Stockton WH (708 mi) | T6: Direct truck — best transport story in network | U6: Best-served True 5. West region GMI losing 1.1pp share, so this is the defensive anchor. Shamrock + Wilson playbook is replicable.
A7: Charlotte | B7: 35.23 | C7: -80.84 | D7: 4 | F7: Watch-list — could promote to True 5 by 2028 | G7: 2.79M | H7: +1.65% | I7: South | J7: EAST (Tiemeyer) | K7: Josh Cohen | L7: US Foods-Charlotte, Sysco-Charlotte | M7: Truist, LendingTree, Honeywell, Lowe's, Bank of America, Duke Energy | N7: Banking, energy, tech, motorsports, healthcare | O7: ~38K | P7: +1% | Q7: +16-20% | R7: Kansas City (897 mi) | S7: Mechanicsburg WH (490 mi) — Atlanta WH (if approved) drops to ~250 mi | T7: Intermodal rail | U7: Strong HQ inflow story. Atlanta WH (if approved) shifts Charlotte from intermodal to direct truck.
A8: Nashville | B8: 36.16 | C8: -86.78 | D8: 4 | F8: Strong territory with growth momentum | G8: 2.04M | H8: +1.57% | I8: South | J8: EAST (Tiemeyer) | K8: Josh Cohen | L8: GFS, Sysco-Nashville | M8: HCA Healthcare, Nissan, Dollar General, Bridgestone | N8: Healthcare, music/entertainment, automotive, logistics | O8: ~31K | P8: +4% | Q8: +17-21% | R8: Kansas City (533 mi) | S8: Mechanicsburg WH (730 mi) | T8: Intermodal — fringe truck range | U8: GMI Index 152 — well above national parity. Strong territory with growth momentum from prior coverage; Josh Cohen now owns the relationship.
A9: Denver | B9: 39.74 | C9: -104.99 | D9: 3 | F9: Solid market, slowing growth — maintain | G9: 3.00M | H9: +1.12% | I9: West | J9: WEST (Mueting) | K9: Shotsie Wilson | L9: Shamrock Foods, US Foods-Denver | M9: Frontier, RE/MAX, Western Union, DaVita | N9: Aerospace, energy (oil & gas), tech, outdoor recreation, hospitality | O9: ~32K | P9: -1% | Q9: +10-13% | R9: Kansas City (605 mi) | S9: Stockton WH (1,100 mi) | T9: Intermodal rail | U9: Mountain West gateway. Shotsie owns AE relationship across CO, MT, WY, ID.
A10: Seattle | B10: 47.61 | C10: -122.33 | D10: 3 | F10: Tech-driven FS demand but slowing | G10: 4.02M | H10: +0.94% | I10: West | J10: WEST (Mueting) | K10: Yoel Sharabi | L10: US Foods-Seattle, Sysco-Seattle | M10: Amazon, Starbucks, Zillow, Expedia | N10: Tech, aerospace, coffee/retail HQs, healthcare, maritime | O10: ~42K | P10: -2% | Q10: +8-11% | R10: Great Falls, MT (~520 mi) | S10: Stockton WH (810 mi) | T10: Long-haul rail | U10: Mature market, regulatory headwinds. Great Falls is the natural mill anchor.
A11: Boston | B11: 42.36 | C11: -71.06 | D11: 2 | F11: Mature market, high cost | G11: 4.94M | H11: +0.52% | I11: Northeast | J11: EAST (Tiemeyer) | K11: Tim Cipriano | L11: PFG-Springfield, Sysco-Boston | M11: GE, Gillette, Liberty Mutual, Vertex | N11: Healthcare, education (Harvard/MIT ecosystem), biotech, financial services | O11: ~48K | P11: -3% | Q11: +3-6% | R11: Buffalo (455 mi) | S11: Mechanicsburg WH (340 mi) | T11: Truck | U11: Mature, slow-growth, expensive. NE region has 56% GMI share already (saturated).
A12: Minneapolis | B12: 44.98 | C12: -93.27 | D12: 2 | F12: Home market, slow growth despite proximity | G12: 3.69M | H12: +0.71% | I12: Central | J12: WEST (Mueting) | K12: Open (Not Covered) | L12: Sysco-Minnesota, Reinhart | M12: Target, Best Buy, US Bancorp, 3M, UnitedHealth, General Mills | N12: Retail HQs, healthcare, food (us!), agriculture, financial services | O12: ~28K | P12: -5% | Q12: +4-7% | R12: Avon, IA (231 mi) | S12: Independence WH (440 mi) | T12: Direct truck | U12: WHQ home market. Central region growing fastest +5.5% but ND-SD-NE-MN-IA-WI territory is uncovered.
A13: Detroit | B13: 42.33 | C13: -83.05 | D13: 1 | F13: Declining metro — defend, do not invest | G13: 4.39M | H13: -0.18% | I13: Central | J13: WEST (Mueting) | K13: Dean Psyhogios | L13: Gordon Food Service, Sysco-Detroit | M13: GM, Ford, Rocket, Penske | N13: Auto, manufacturing (declining), healthcare | O13: ~45K | P13: -9% | Q13: -2 to +1% | R13: Buffalo (290 mi) | S13: Mechanicsburg WH (440 mi) | T13: Direct truck | U13: Aging demographics, shrinking workforce. Dean owns KY-OH-IN-IL-MI under James.
A14: Cleveland | B14: 41.5 | C14: -81.69 | D14: 1 | F14: Cold spot — aging and declining | G14: 2.06M | H14: -0.31% | I14: Central | J14: WEST (Mueting) | K14: Dean Psyhogios | L14: PFG-Cleveland, Sysco-Cleveland | M14: Sherwin-Williams, Progressive, KeyCorp | N14: Healthcare (Cleveland Clinic), manufacturing, banking, insurance | O14: ~22K | P14: -11% | Q14: -3 to 0% | R14: Buffalo (188 mi) | S14: Mechanicsburg WH (290 mi) | T14: Direct truck | U14: Shrinking population. Cleveland Clinic is the only real anchor.
A15: Buffalo | B15: 42.89 | C15: -78.88 | D15: 1 | F15: Mill home market — defend the base | G15: 1.16M | H15: -0.22% | I15: Northeast | J15: EAST (Tiemeyer) | K15: Kevin Karbo | L15: Sysco-Albany, Upstate distributors | M15: M&T Bank, New Era, Moog | N15: Healthcare, education, manufacturing, finance | O15: ~14K | P15: -7% | Q15: -2 to 0% | R15: Buffalo (co-located) | S15: Buffalo WH (co-located) | T15: Local truck | U15: Mill home. Kevin owns WV-Western PA-Western NY.
A16: New York | B16: 40.71 | C16: -74.01 | D16: 2 | I16: Northeast | J16: EAST (Tiemeyer) | K16: Conrad Chan & Chuck Bootier | L16: Driscoll Foods, US Foods-Metro NY | M16: JPMorgan Chase & Co, Goldman Sachs Group, Morgan Stanley, AMEX, BlackRock, Pfizer, Verizon | N16: Finance, media, hospitality, healthcare, education | O16: 78.8M lb GMI Â· Index 183 Â· 57.5% share | P16: +8.6% GMI | Q16: 0 to +2% | R16: Buffalo (370 mi) | S16: Mechanicsburg WH (180 mi) | T16: Direct truck | U16: Highest GMI share in the country at 57.5%. Mature and saturated â defend the base, do not over-invest. Conrad & Chuck own NYC, Long Island, NJ.
A17: Los Angeles | B17: 34.05 | C17: -118.41 | D17: 3 | I17: West | J17: WEST (Mueting) | K17: Nancy Muller | L17: BakeMark-LA, Greco SoCal, PFS-SoCal | M17: The Walt Disney Co, SpaceX, Warner Bros Entertainment | N17: Entertainment, aerospace, logistics, hospitality, manufacturing | O17: Territory data (West, not in Circana panel) | P17: See territory | Q17: -1 to +1% | R17: Vernon, CA (in-market, ~5 mi) | S17: Stockton WH (350 mi) | T17: Direct truck â best cost-to-serve in network | U17: Vernon mill sits inside the market, so cost-to-serve is the best anywhere. Mature dense market, but independent Hispanic bakeries are real whitespace. Replicate the El Super and Northgate model at the street level. Nancy owns Southern CA and HI.
A18: Chicago | B18: 41.88 | C18: -87.63 | D18: 2 | I18: Central | J18: WEST (Mueting) | K18: Dean Psyhogios | L18: Gordon Food Service, US Foods-Chicago | M18: United Airlines, ADM, Conagra, MondelÄz | N18: Finance, manufacturing, logistics, food, healthcare | O18: 5.07M lb GMI Â· Index 62 Â· 17.2% share | P18: -2.0% GMI | Q18: -1 to +1% | R18: Avon, IA (330 mi) | S18: Independence WH (510 mi) | T18: Truck / intermodal | U18: Index 62 means real under-penetration, but the market is declining and mature. Acknowledge our strong rep while focusing investment on growth-exposure metros. Dean owns IL-IN-OH-KY-MI.
A19: Washington DC | B19: 38.91 | C19: -77.04 | D19: 3 | I19: South | J19: EAST (Tiemeyer) | K19: Lynn Allen | L19: US Foods-Manassas, Sysco-Baltimore-Washington | M19: Danaher, Fannie Mae, Carlyle Group, Xylem, Amtrak | N19: Government, defense, consulting, healthcare, education | O19: 12.5M lb GMI Â· Index 102 Â· 31.1% share | P19: +5.7% GMI | Q19: +6-9% | R19: Buffalo (370 mi) | S19: Mechanicsburg WH (120 mi) | T19: Direct truck | U19: At parity with healthy +5.7% GMI growth. Defend share and develop. Lynn owns VA, MD, DC, DE, Eastern NC.
A20: Philadelphia | B20: 39.95 | C20: -75.17 | D20: 3 | I20: Northeast | J20: EAST (Tiemeyer) | K20: Lynn Allen | L20: US Foods-Philadelphia, Performance Foodservice | M20: Comcast, Cencora, Aramark, Toll Brothers | N20: Healthcare, pharma, education, finance, logistics | O20: 17.5M lb GMI Â· Index 104 Â· 32.0% share | P20: +0.3% GMI | Q20: +2-4% | R20: Buffalo (370 mi) | S20: Mechanicsburg WH (95 mi) | T20: Direct truck | U20: At national parity and stable. Mechanicsburg WH at 95 mi gives strong cost-to-serve. Hold share. Chuck owns Eastern PA, NJ, Eastern NY.
A21: Miami | B21: 25.86 | C21: -80.27 | D21: 3 | I21: South | J21: EAST (Tiemeyer) | K21: Jeffrey Santiago | L21: Cheney Brothers, Sysco-South Florida | M21: Palantir, World Kinect Corp, Lennar Corp, Ryder System, Royal Caribbean Group | N21: Tourism, trade, finance, healthcare, hospitality | O21: 9.89M lb GMI Â· Index 102 Â· 23.0% share | P21: -1.1% GMI | Q21: +5-8% | R21: Buffalo (far) | S21: Orlando WH (205 mi) | T21: Truck from Orlando WH | U21: At parity but flat. Dense Hispanic population makes independent Hispanic bakeries a real whitespace lane. Jeffrey owns all FL except the Panhandle.
A22: San Francisco-Oakland | B22: 37.8 | C22: -122.27 | D22: 3 | I22: West | J22: WEST (Mueting) | K22: Yoel Sharabi | L22: US Foods-Bay Area, Sysco-SF, Chefs Warehouse-West | M22: Salesforce, Wells Fargo | N22: Tech, finance, tourism, hospitality, biotech | O22: Territory data (West, not in Circana panel) | P22: See territory | Q22: 0 to +2% | R22: Vernon, CA (380 mi) | S22: Stockton WH (75 mi) | T22: Direct truck from Stockton WH | U22: Premium artisan and restaurant demand served off Stockton WH. Mature and expensive, defend the base. Yoel owns Northern CA.
A23: Riverside | B23: 33.98 | C23: -117.38 | D23: 4 | I23: West | J23: WEST (Mueting) | K23: Nancy Muller | L23: Sysco-Riverside, US Foods-Corona, BakeMark | M23: Bourns, Inc, K&N Engineering, Best Best & Krieger | N23: Logistics, warehousing, manufacturing, healthcare, retail | O23: Territory data (West, not in Circana panel) | P23: See territory | Q23: +8-11% | R23: Vernon, CA (60 mi) | S23: Stockton WH (400 mi) | T23: Direct truck from Vernon | U23: One of the fastest-growing population centers in California and a national logistics hub, close to the Vernon mill. Strong develop play with Hispanic ISB upside. Nancy owns Southern CA.
A24: San Diego | B24: 32.72 | C24: -117.16 | D24: 3 | I24: West | J24: WEST (Mueting) | K24: Nancy Muller | L24: BakeMark-San Diego, US Foods-San Diego, Sysco | M24: Qualcomm, LPL Financial, Qualcomm | N24: Defense, biotech, tourism, hospitality, cross-border trade | O24: Territory data (West, not in Circana panel) | P24: See territory | Q24: +3-5% | R24: Vernon, CA (130 mi) | S24: Stockton WH (480 mi) | T24: Direct truck from Vernon | U24: Second-largest SoCal market with a heavy Hispanic base, served off the Vernon mill. Independent Hispanic bakery whitespace mirrors the LA model. Nancy owns Southern CA.
A25: Baltimore | B25: 39.29 | C25: -76.61 | D25: 3 | I25: South | J25: EAST (Tiemeyer) | K25: Lynn Allen | L25: US Foods-Baltimore, Sysco-Baltimore | M25: Under Armour, Johns Hopkins, T. Rowe Price Group | N25: Healthcare, biotech, defense, logistics, education | O25: 4.84M lb GMI Â· Index 90 Â· 27.6% share | P25: -0.5% GMI | Q25: +3-5% | R25: Buffalo (380 mi) | S25: Mechanicsburg WH (95 mi) | T25: Direct truck | U25: Slightly below parity and flat, but Mechanicsburg WH at 95 mi makes it cheap to serve. Steady-hold. Lynn owns MD, VA, DC, DE.
A26: St. Louis | B26: 38.63 | C26: -90.2 | D26: 4 | I26: Central | J26: WEST (Mueting) | K26: Tim Ryan | L26: US Foods-St. Louis, Sysco-St. Louis | M26: Enterprise, Edward Jones, Anheuser-Busch InBev | N26: Healthcare, finance, agribusiness, logistics, beverage | O26: 3.34M lb GMI Â· Index 122 Â· 37.0% share | P26: +21.1% GMI | Q26: +1-3% | R26: Kansas City (250 mi) | S26: Independence WH (250 mi) | T26: Truck from KC mill | U26: High 37% share with GMI up 21.1%, served cheaply off the KC mill. Defend and ride the momentum. Tim Ryan owns MO.
A27: Orlando | B27: 28.42 | C27: -81.3 | D27: 4 | I27: South | J27: EAST (Tiemeyer) | K27: Jeffrey Santiago | L27: Cheney Brothers, Sysco-Central Florida | M27: Darden Restaurants, Travel + Leisure Co, AAA, Marriot | N27: Tourism, hospitality, healthcare, tech, defense sim | O27: 10.3M lb GMI Â· Index 120 Â· 33.7% share | P27: +6.3% GMI | Q27: +18-22% | R27: Buffalo (far) | S27: Orlando WH (~12 mi, beside facility) | T27: Direct truck â best SE cost-to-serve | U27: Index 120, +6.3% GMI, and Orlando WH essentially co-located gives the best cost-to-serve in the Southeast. Pin nudged off the warehouse marker. Jeffrey owns FL ex-Panhandle.
... A51: Birmingham | B51: 33.52 | C51: -86.81 | D51: 3 | I51: South | J51: EAST (Tiemeyer) | K51: Josh Cohen | L51: US Foods-Birmingham, Sysco-Alabama | M51: Healthcare (UAB), Regions Financial Corporation | N51: Healthcare, finance, manufacturing, logistics | O51: 1.73M lb GMI Â· Index 93 Â· 27.6% share | P51: -0.9% GMI | Q51: +2-4% | R51: Kansas City (660 mi) | S51: Orlando WH (470 mi) | T51: Truck / intermodal | U51: Near parity and roughly flat. Hold and develop. Josh covers AL, GA, SC, Western NC, TN.

Sheet Source Notes
A1: Source | B1: Use in workbook
A2: national.html | B2: Primary city list, map metadata, AE/zone/distributor, HQ inflow, industries, transport, map insights, True 5 rank and map score.
A3: Copy of Feb 2026 Flour by DMA - 5.26.26.xlsx | B3: DMA-level total flour market size, GMI lbs, GMI share, YoY growth, calculated GMI index where available. Does not cover West Coast metros.
A4: Copy of New Report_511 Circana Data.xlsx | B4: Regional Circana validation for South/West/Central/Northeast directional context.
A5: Copy of FSI Territory Volume Pull F26 annualized April 2026 for Jake.xlsx | B5: F26 annualized internal territory volume context, including 17.7M CWT annualized Flour Distribution figure.
A6: AE/Field insights | B6: Used qualitatively for action/tier explanations: Texas/Sysco realism, Atlanta/Orlando warehouse logic, West clean-label/enzyme/tortilla needs, two-truck minimum, product fit, and distributor dynamics.
